0
1
2
3
4
5
6
7
8
9
10
11
12
13
14
15
16
17
18
19
0
1
2
3
4
5
6
7
8
9
10
11
12
13
14
15
16
17
18
19
Epochs:   7% 1/15 [00:48<11:16, 48.30s/it]
Trajectories:   0% 0/4 [00:00<?, ?it/s]
0
1
2
3
4
5
6
7
8
9
10
11
12
13
14
15
16
17
18
19
0
1
2
3
4
5
6
7
8
9
10
11
12
13
14
15
16
17
18

Epochs:   7% 1/15 [01:18<18:23, 78.81s/it]
Traceback (most recent call last):
  File "/home/abdulmajeed/Documents/hyper-graph-nets/main.py", line 41, in <module>
    args = sys.argv[1]
IndexError: list index out of range
During handling of the above exception, another exception occurred:
Traceback (most recent call last):
  File "/home/abdulmajeed/anaconda3/envs/hypergraphnet/lib/python3.8/site-packages/matplotlib/animation.py", line 234, in saving
    yield self
  File "/home/abdulmajeed/anaconda3/envs/hypergraphnet/lib/python3.8/site-packages/matplotlib/animation.py", line 1093, in save
    writer.grab_frame(**savefig_kwargs)
  File "/home/abdulmajeed/anaconda3/envs/hypergraphnet/lib/python3.8/site-packages/matplotlib/animation.py", line 506, in grab_frame
    self.fig.savefig(
  File "/home/abdulmajeed/anaconda3/envs/hypergraphnet/lib/python3.8/site-packages/matplotlib/figure.py", line 3046, in savefig
    self.canvas.print_figure(fname, **kwargs)
  File "/home/abdulmajeed/anaconda3/envs/hypergraphnet/lib/python3.8/site-packages/matplotlib/backend_bases.py", line 2319, in print_figure
    result = print_method(
  File "/home/abdulmajeed/anaconda3/envs/hypergraphnet/lib/python3.8/site-packages/matplotlib/backend_bases.py", line 1648, in wrapper
    return func(*args, **kwargs)
  File "/home/abdulmajeed/anaconda3/envs/hypergraphnet/lib/python3.8/site-packages/matplotlib/_api/deprecation.py", line 415, in wrapper
    return func(*inner_args, **inner_kwargs)
  File "/home/abdulmajeed/anaconda3/envs/hypergraphnet/lib/python3.8/site-packages/matplotlib/backends/backend_agg.py", line 483, in print_raw
    FigureCanvasAgg.draw(self)
  File "/home/abdulmajeed/anaconda3/envs/hypergraphnet/lib/python3.8/site-packages/matplotlib/backends/backend_agg.py", line 436, in draw
    self.figure.draw(self.renderer)
  File "/home/abdulmajeed/anaconda3/envs/hypergraphnet/lib/python3.8/site-packages/matplotlib/artist.py", line 73, in draw_wrapper
    result = draw(artist, renderer, *args, **kwargs)
  File "/home/abdulmajeed/anaconda3/envs/hypergraphnet/lib/python3.8/site-packages/matplotlib/artist.py", line 50, in draw_wrapper
    return draw(artist, renderer)
  File "/home/abdulmajeed/anaconda3/envs/hypergraphnet/lib/python3.8/site-packages/matplotlib/figure.py", line 2837, in draw
    mimage._draw_list_compositing_images(
  File "/home/abdulmajeed/anaconda3/envs/hypergraphnet/lib/python3.8/site-packages/matplotlib/image.py", line 132, in _draw_list_compositing_images
    a.draw(renderer)
  File "/home/abdulmajeed/anaconda3/envs/hypergraphnet/lib/python3.8/site-packages/matplotlib/artist.py", line 50, in draw_wrapper
    return draw(artist, renderer)
  File "/home/abdulmajeed/anaconda3/envs/hypergraphnet/lib/python3.8/site-packages/mpl_toolkits/mplot3d/axes3d.py", line 451, in draw
    for artist in sorted(collections_and_patches,
  File "/home/abdulmajeed/anaconda3/envs/hypergraphnet/lib/python3.8/site-packages/mpl_toolkits/mplot3d/axes3d.py", line 440, in do_3d_projection
    return artist.do_3d_projection()
  File "/home/abdulmajeed/anaconda3/envs/hypergraphnet/lib/python3.8/site-packages/matplotlib/_api/deprecation.py", line 389, in wrapper
    return func(*inner_args, **inner_kwargs)
  File "/home/abdulmajeed/anaconda3/envs/hypergraphnet/lib/python3.8/site-packages/mpl_toolkits/mplot3d/art3d.py", line 823, in do_3d_projection
    z_segments_2d = sorted(
  File "/home/abdulmajeed/anaconda3/envs/hypergraphnet/lib/python3.8/site-packages/mpl_toolkits/mplot3d/art3d.py", line 827, in <lambda>
    key=lambda x: x[0], reverse=True)
  File "/snap/pycharm-community/312/plugins/python-ce/helpers/pydev/_pydevd_bundle/pydevd_trace_dispatch_regular.py", line 421, in __call__
    frame_cache_key = (frame.f_code.co_firstlineno, frame.f_code.co_name, frame.f_code.co_filename)
KeyboardInterrupt
During handling of the above exception, another exception occurred:
Traceback (most recent call last):
  File "/snap/pycharm-community/312/plugins/python-ce/helpers/pydev/pydevd.py", line 2195, in <module>
    main()
  File "/snap/pycharm-community/312/plugins/python-ce/helpers/pydev/pydevd.py", line 2177, in main
    globals = debugger.run(setup['file'], None, None, is_module)
  File "/snap/pycharm-community/312/plugins/python-ce/helpers/pydev/pydevd.py", line 1489, in run
    return self._exec(is_module, entry_point_fn, module_name, file, globals, locals)
  File "/snap/pycharm-community/312/plugins/python-ce/helpers/pydev/pydevd.py", line 1496, in _exec
    pydev_imports.execfile(file, globals, locals)  # execute the script
  File "/snap/pycharm-community/312/plugins/python-ce/helpers/pydev/_pydev_imps/_pydev_execfile.py", line 18, in execfile
    exec(compile(contents+"\n", file, 'exec'), glob, loc)
  File "/home/abdulmajeed/Documents/hyper-graph-nets/main.py", line 44, in <module>
    main()
  File "/home/abdulmajeed/Documents/hyper-graph-nets/main.py", line 33, in main
    task.run_iterations()
  File "/home/abdulmajeed/Documents/hyper-graph-nets/src/tasks/MeshTask.py", line 105, in run_iterations
    dir_dict = self.select_plotting(task_name)
  File "/home/abdulmajeed/Documents/hyper-graph-nets/src/tasks/MeshTask.py", line 147, in select_plotting
    dir_1 = self._save_plot(a, w, task_name)
  File "/home/abdulmajeed/Documents/hyper-graph-nets/src/tasks/MeshTask.py", line 390, in _save_plot
    animation.save(dir, writer=writervideo)
  File "/home/abdulmajeed/anaconda3/envs/hypergraphnet/lib/python3.8/site-packages/matplotlib/animation.py", line 1093, in save
    writer.grab_frame(**savefig_kwargs)
  File "/home/abdulmajeed/anaconda3/envs/hypergraphnet/lib/python3.8/contextlib.py", line 131, in __exit__
    self.gen.throw(type, value, traceback)
  File "/home/abdulmajeed/anaconda3/envs/hypergraphnet/lib/python3.8/site-packages/matplotlib/animation.py", line 236, in saving
    self.finish()
  File "/home/abdulmajeed/anaconda3/envs/hypergraphnet/lib/python3.8/site-packages/matplotlib/animation.py", line 512, in finish
    self._frames[0].save(
IndexError: list index out of range